Workbook

Sheet Dashboard
A1: WEALTH GLIDE PATH — QUADRANT ROTATION FRAMEWORK
A2: Age-based risk glide with regime-conditional return engine | Backtest Jan 2007–Sep 2026 | Prepared September 09, 2026 | Forward ledger live
A4: Inputs — edit yellow cells
A5: Current age | C5: 25
A6: Target end age | C6: 65
A7: Starting balance ($) | C7: 11000
A8: Year-1 monthly contribution ($) | C8: 1500
A9: Contribution cap ($/mo) | C9: 40000
A10: Backtest return haircut | C10: 0.25 | D10: discount on backtested returns; 0% = raw backtest
A11: ST tax rate on gains (fed+state) | C11: 0.24 | D11: rotation gains are ~all short-term (median regime 2 months) — taxed annually
A12: LT cap-gains rate | C12: 0.15 | D12: applied to buy-and-hold benchmarks at liquidation (Comparison)
A13: Risk glide path — choose a tier for each 5-year block
A14: ="Age "&($C$5+0*5)&"–"&($C$5+1*5) | C14: VAGG | E14: =MAX(0,MIN(5,($C$6-$C$5)-0*5))/MAX(1,$C$6-$C$5) | F14: =INDEX(Settings!$D$13:$D$16,MATCH($C14,Settings!$A$13:$A$16,0)) | G14: =INDEX(Settings!$G$13:$G$16,MATCH($C14,Settings!$A$13:$A$16,0))
A15: ="Age "&($C$5+1*5)&"–"&($C$5+2*5) | C15: VAGG | E15: =MAX(0,MIN(5,($C$6-$C$5)-1*5))/MAX(1,$C$6-$C$5) | F15: =INDEX(Settings!$D$13:$D$16,MATCH($C15,Settings!$A$13:$A$16,0)) | G15: =INDEX(Settings!$G$13:$G$16,MATCH($C15,Settings!$A$13:$A$16,0))
A16: ="Age "&($C$5+2*5)&"–"&($C$5+3*5) | C16: AGG | E16: =MAX(0,MIN(5,($C$6-$C$5)-2*5))/MAX(1,$C$6-$C$5) | F16: =INDEX(Settings!$D$13:$D$16,MATCH($C16,Settings!$A$13:$A$16,0)) | G16: =INDEX(Settings!$G$13:$G$16,MATCH($C16,Settings!$A$13:$A$16,0))
A17: ="Age "&($C$5+3*5)&"–"&($C$5+4*5) | C17: AGG | E17: =MAX(0,MIN(5,($C$6-$C$5)-3*5))/MAX(1,$C$6-$C$5) | F17: =INDEX(Settings!$D$13:$D$16,MATCH($C17,Settings!$A$13:$A$16,0)) | G17: =INDEX(Settings!$G$13:$G$16,MATCH($C17,Settings!$A$13:$A$16,0))
A18: ="Age "&($C$5+4*5)&"–"&($C$5+5*5) | C18: MOD | E18: =MAX(0,MIN(5,($C$6-$C$5)-4*5))/MAX(1,$C$6-$C$5) | F18: =INDEX(Settings!$D$13:$D$16,MATCH($C18,Settings!$A$13:$A$16,0)) | G18: =INDEX(Settings!$G$13:$G$16,MATCH($C18,Settings!$A$13:$A$16,0))
A19: ="Age "&($C$5+5*5)&"–"&($C$5+6*5) | C19: MOD | E19: =MAX(0,MIN(5,($C$6-$C$5)-5*5))/MAX(1,$C$6-$C$5) | F19: =INDEX(Settings!$D$13:$D$16,MATCH($C19,Settings!$A$13:$A$16,0)) | G19: =INDEX(Settings!$G$13:$G$16,MATCH($C19,Settings!$A$13:$A$16,0))
A20: ="Age "&($C$5+6*5)&"–"&($C$5+7*5) | C20: MOD | E20: =MAX(0,MIN(5,($C$6-$C$5)-6*5))/MAX(1,$C$6-$C$5) | F20: =INDEX(Settings!$D$13:$D$16,MATCH($C20,Settings!$A$13:$A$16,0)) | G20: =INDEX(Settings!$G$13:$G$16,MATCH($C20,Settings!$A$13:$A$16,0))
A21: ="Age "&($C$5+7*5)&"–"&($C$5+8*5) | C21: CONS | E21: =MAX(0,MIN(5,($C$6-$C$5)-7*5))/MAX(1,$C$6-$C$5) | F21: =INDEX(Settings!$D$13:$D$16,MATCH($C21,Settings!$A$13:$A$16,0)) | G21: =INDEX(Settings!$G$13:$G$16,MATCH($C21,Settings!$A$13:$A$16,0))
A22: Default glide: VAGG to 35, AGG to 45, MOD to 60, CONS to 65. Grey columns = weight in horizon / tier stats (used by Statistics).
A24: Outcome (after-tax, after-haircut)
A25: Current tier / net growth rate | C25: =$C$14&" · "&TEXT($F$14,"0.0%")&"/yr"
A26: Current monthly contribution | C26: =MIN($C$9,Settings!$B$19)
A27: Expected balance at end age | C27: =INDEX(Projection!$E:$E,(($C$6-$C$5)*12)+4)
A28: Low / High (±1 s.e.) | C28: =TEXT(INDEX(Projection!$F:$F,(($C$6-$C$5)*12)+4),"$#,##0")&" / "&TEXT(INDEX(Projection!$G:$G,(($C$6-$C$5)*12)+4),"$#,##0")
A29: Total contributed | C29: =$C$7+SUM(Projection!$D$5:INDEX(Projection!$D:$D,(($C$6-$C$5)*12)+4))
A30: Investment growth | C30: =C27-C29
A31: Wealth multiple (balance / contributed) | C31: =IF(C29=0,0,C27/C29)
A33: Backtest-derived planning model; pending forward validation (paper ledger). Deep statistics on the next sheet. Not investment advice.

Sheet Statistics
A1: DEEP STATISTICS — BACKTEST EVIDENCE & REGIME ANALYTICS
A2: Matrix v9 (gold instrument by regime — bullion in Reflation, miners in Deflation for AGG/VAGG; AGG Reflation leverage on the energy leg; conditional-duration S, washout-conditional rebound slice, R momentum tilt, regime-gated short book behind a global include-shorts switch), monthly-only execution — intra-month mechanisms tested and rejected under honest T+1 modeling. Leveraged instruments simulated pre-2010. Out-of-sample framework validation: 1987-2007 replication. Forward: paper/ledger.csv.
A4: 1 · Full-period & crisis-year performance
A5: Strategy | B5: CAGR | C5: Sortino | D5: Sharpe | E5: Max DD | F5: Beta | G5: 2008 | H5: 2020 | I5: 2022 | J5: 2025 | K5: 2026 YTD
A6: CONS | B6: 0.0981 | C6: 1.6213 | D6: 1.1678 | E6: -0.1021 | F6: 0.1699 | G6: 0.1382 | H6: 0.1297 | I6: 0.0187 | J6: 0.2063 | K6: 0.1358
A7: MOD | B7: 0.1543 | C7: 1.7335 | D7: 1.2537 | E7: -0.1433 | F7: 0.3303 | G7: 0.1463 | H7: 0.2998 | I7: 0.0115 | J7: 0.3012 | K7: 0.1986
A8: AGG | B8: 0.2728 | C8: 1.4118 | D8: 1.0856 | E8: -0.3315 | F8: 0.6431 | G8: 0.3462 | H8: 0.867 | I8: -0.0931 | J8: 0.4396 | K8: 0.3178
A9: VAGG | B9: 0.3532 | C9: 1.22 | D9: 0.9646 | E9: -0.4682 | F9: 1.0242 | G9: 0.4413 | H9: 1.402 | I9: -0.3106 | J9: 0.4968 | K9: 0.3254
A10: SPY B&H | B10: 0.1098 | C10: 0.6869 | D10: 0.5612 | E10: -0.5519 | F10: 1 | G10: -0.3679 | H10: 0.1833 | I10: -0.1818 | J10: 0.1772 | K10: 0.1347
A11: QQQ B&H | B11: 0.1645 | C11: 0.9613 | D11: 0.7405 | E11: -0.534 | F11: 1.0473 | G11: -0.4173 | H11: 0.4841 | I11: -0.3258 | J11: 0.2077 | K11: 0.2085
A13: 2 · Annualized return by tier × regime (conditional)
B14: Growth | C14: Reflation | D14: Stagflation | E14: Deflation | F14: Blended (mix)
A15: CONS | B15: =(1+Data!B6)^12-1 | C15: =(1+Data!C6)^12-1 | D15: =(1+Data!D6)^12-1 | E15: =(1+Data!E6)^12-1 | F15: =Settings!C13
A16: MOD | B16: =(1+Data!B7)^12-1 | C16: =(1+Data!C7)^12-1 | D16: =(1+Data!D7)^12-1 | E16: =(1+Data!E7)^12-1 | F16: =Settings!C14
A17: AGG | B17: =(1+Data!B8)^12-1 | C17: =(1+Data!C8)^12-1 | D17: =(1+Data!D8)^12-1 | E17: =(1+Data!E8)^12-1 | F17: =Settings!C15
A18: VAGG | B18: =(1+Data!B9)^12-1 | C18: =(1+Data!C9)^12-1 | D18: =(1+Data!D9)^12-1 | E18: =(1+Data!E9)^12-1 | F18: =Settings!C16
A20: 3 · In-regime Sharpe by tier × regime
B21: Growth | C21: Reflation | D21: Stagflation | E21: Deflation
A22: CONS | B22: =IF(Data!B13=0,0,((1+Data!B6)^12-1-Data!$B$23)/(Data!B13*SQRT(12))) | C22: =IF(Data!C13=0,0,((1+Data!C6)^12-1-Data!$B$23)/(Data!C13*SQRT(12))) | D22: =IF(Data!D13=0,0,((1+Data!D6)^12-1-Data!$B$23)/(Data!D13*SQRT(12))) | E22: =IF(Data!E13=0,0,((1+Data!E6)^12-1-Data!$B$23)/(Data!E13*SQRT(12)))
A23: MOD | B23: =IF(Data!B14=0,0,((1+Data!B7)^12-1-Data!$B$23)/(Data!B14*SQRT(12))) | C23: =IF(Data!C14=0,0,((1+Data!C7)^12-1-Data!$B$23)/(Data!C14*SQRT(12))) | D23: =IF(Data!D14=0,0,((1+Data!D7)^12-1-Data!$B$23)/(Data!D14*SQRT(12))) | E23: =IF(Data!E14=0,0,((1+Data!E7)^12-1-Data!$B$23)/(Data!E14*SQRT(12)))
A24: AGG | B24: =IF(Data!B15=0,0,((1+Data!B8)^12-1-Data!$B$23)/(Data!B15*SQRT(12))) | C24: =IF(Data!C15=0,0,((1+Data!C8)^12-1-Data!$B$23)/(Data!C15*SQRT(12))) | D24: =IF(Data!D15=0,0,((1+Data!D8)^12-1-Data!$B$23)/(Data!D15*SQRT(12))) | E24: =IF(Data!E15=0,0,((1+Data!E8)^12-1-Data!$B$23)/(Data!E15*SQRT(12)))
A25: VAGG | B25: =IF(Data!B16=0,0,((1+Data!B9)^12-1-Data!$B$23)/(Data!B16*SQRT(12))) | C25: =IF(Data!C16=0,0,((1+Data!C9)^12-1-Data!$B$23)/(Data!C16*SQRT(12))) | D25: =IF(Data!D16=0,0,((1+Data!D9)^12-1-Data!$B$23)/(Data!D16*SQRT(12))) | E25: =IF(Data!E16=0,0,((1+Data!E9)^12-1-Data!$B$23)/(Data!E16*SQRT(12)))
A27: 4 · Regime structure | B27: Growth | C27: Reflation | D27: Stagflation | E27: Deflation
A28: Share of months | B28: =Data!B20 | C28: =Data!C20 | D28: =Data!D20 | E28: =Data!E20
A29: Avg duration (months) | B29: =Data!B21 | C29: =Data!C21 | D29: =Data!D21 | E29: =Data!E21
A31: 5 · Outcome distribution at end age (glide-weighted approximation)
A32: Glide-weighted annual return (after-tax) | B32: =SUMPRODUCT(Dashboard!$E$14:$E$21,Dashboard!$F$14:$F$21)
A33: Glide-weighted annual sd | B33: =SUMPRODUCT(Dashboard!$E$14:$E$21,Dashboard!$G$14:$G$21)
A35: Percentile | B35: z | C35: Annual rate | D35: Final balance (approx)
A36: P10 | B36: -1.2816 | C36: =$B$32+B36*$B$33/SQRT(MAX(1,Settings!$B$9)) | D36: =IF(ABS(((1+C36)^(1/12)-1)-Settings!$B$60)<0.000001,Dashboard!$C$7*(1+((1+C36)^(1/12)-1))^(Settings!$B$9*12)+Dashboard!$C$8*(Settings!$B$9*12)*(1+((1+C36)^(1/12)-1))^((Settings!$B$9*12)-1),Dashboard!$C$7*(1+((1+C36)^(1/12)-1))^(Settings!$B$9*12)+Dashboard!$C$8*(((1+((1+C36)^(1/12)-1))^(Settings!$B$9*12))-((1+Settings!$B$60)^(Settings!$B$9*12)))/(((1+C36)^(1/12)-1)-Settings!$B$60))
A37: P25 | B37: -0.6745 | C37: =$B$32+B37*$B$33/SQRT(MAX(1,Settings!$B$9)) | D37: =IF(ABS(((1+C37)^(1/12)-1)-Settings!$B$60)<0.000001,Dashboard!$C$7*(1+((1+C37)^(1/12)-1))^(Settings!$B$9*12)+Dashboard!$C$8*(Settings!$B$9*12)*(1+((1+C37)^(1/12)-1))^((Settings!$B$9*12)-1),Dashboard!$C$7*(1+((1+C37)^(1/12)-1))^(Settings!$B$9*12)+Dashboard!$C$8*(((1+((1+C37)^(1/12)-1))^(Settings!$B$9*12))-((1+Settings!$B$60)^(Settings!$B$9*12)))/(((1+C37)^(1/12)-1)-Settings!$B$60))
A38: P50 (median) | B38: 0 | C38: =$B$32+B38*$B$33/SQRT(MAX(1,Settings!$B$9)) | D38: =IF(ABS(((1+C38)^(1/12)-1)-Settings!$B$60)<0.000001,Dashboard!$C$7*(1+((1+C38)^(1/12)-1))^(Settings!$B$9*12)+Dashboard!$C$8*(Settings!$B$9*12)*(1+((1+C38)^(1/12)-1))^((Settings!$B$9*12)-1),Dashboard!$C$7*(1+((1+C38)^(1/12)-1))^(Settings!$B$9*12)+Dashboard!$C$8*(((1+((1+C38)^(1/12)-1))^(Settings!$B$9*12))-((1+Settings!$B$60)^(Settings!$B$9*12)))/(((1+C38)^(1/12)-1)-Settings!$B$60))
A39: P75 | B39: 0.6745 | C39: =$B$32+B39*$B$33/SQRT(MAX(1,Settings!$B$9)) | D39: =IF(ABS(((1+C39)^(1/12)-1)-Settings!$B$60)<0.000001,Dashboard!$C$7*(1+((1+C39)^(1/12)-1))^(Settings!$B$9*12)+Dashboard!$C$8*(Settings!$B$9*12)*(1+((1+C39)^(1/12)-1))^((Settings!$B$9*12)-1),Dashboard!$C$7*(1+((1+C39)^(1/12)-1))^(Settings!$B$9*12)+Dashboard!$C$8*(((1+((1+C39)^(1/12)-1))^(Settings!$B$9*12))-((1+Settings!$B$60)^(Settings!$B$9*12)))/(((1+C39)^(1/12)-1)-Settings!$B$60))
A40: P90 | B40: 1.2816 | C40: =$B$32+B40*$B$33/SQRT(MAX(1,Settings!$B$9)) | D40: =IF(ABS(((1+C40)^(1/12)-1)-Settings!$B$60)<0.000001,Dashboard!$C$7*(1+((1+C40)^(1/12)-1))^(Settings!$B$9*12)+Dashboard!$C$8*(Settings!$B$9*12)*(1+((1+C40)^(1/12)-1))^((Settings!$B$9*12)-1),Dashboard!$C$7*(1+((1+C40)^(1/12)-1))^(Settings!$B$9*12)+Dashboard!$C$8*(((1+((1+C40)^(1/12)-1))^(Settings!$B$9*12))-((1+Settings!$B$60)^(Settings!$B$9*12)))/(((1+C40)^(1/12)-1)-Settings!$B$60))
A42: Percentiles band the average growth rate; within-horizon drawdowns exceed these paths (see Max DD above). Contribution schedule approximated as smooth growth, cap ignored — Projection is exact.

Sheet Comparison
A1: COMPARISON — COMMON PORTFOLIOS VS THE GLIDE PATH
A2: Identical window (Jan 2007–Sep 2026), dividends included. Benchmark stats are data (blue); tier rows link to Statistics (green).
A4: 1 · Historical risk & return
A5: Portfolio | B5: CAGR | C5: Sortino | D5: Sharpe | E5: Max DD | F5: Beta | G5: 2008 | H5: 2022
A6: S&P 500 (SPY) | B6: 0.1098 | C6: 0.69 | D6: 0.56 | E6: -0.5519 | F6: 1 | G6: -0.3679 | H6: -0.1818
A7: Nasdaq 100 (QQQ) | B7: 0.1645 | C7: 0.96 | D7: 0.74 | E7: -0.534 | F7: 1.05 | G7: -0.4173 | H7: -0.3258
A8: Dow Jones (DIA) | B8: 0.0978 | C8: 0.64 | D8: 0.51 | E8: -0.5187 | F8: 0.92 | G8: -0.3214 | H8: -0.0702
A9: 60/40 (SPY/AGG) | B9: 0.0817 | C9: 0.73 | D9: 0.59 | E9: -0.347 | F9: 0.6 | G9: -0.1997 | H9: -0.1562
A10: All bonds (AGG) | B10: 0.0298 | C10: 0.36 | D10: 0.3 | E10: -0.1843 | F10: 0 | G10: 0.079 | H10: -0.1302
A11: Gold (GLD) | B11: 0.0998 | C11: 0.71 | D11: 0.53 | E11: -0.4556 | F11: 0.05 | G11: 0.0492 | H11: -0.0077
A12: Rotation CONS | B12: =Statistics!B6 | C12: =Statistics!C6 | D12: =Statistics!D6 | E12: =Statistics!E6 | F12: =Statistics!F6 | G12: =Statistics!G6 | H12: =Statistics!I6
A13: Rotation MOD | B13: =Statistics!B7 | C13: =Statistics!C7 | D13: =Statistics!D7 | E13: =Statistics!E7 | F13: =Statistics!F7 | G13: =Statistics!G7 | H13: =Statistics!I7
A14: Rotation AGG | B14: =Statistics!B8 | C14: =Statistics!C8 | D14: =Statistics!D8 | E14: =Statistics!E8 | F14: =Statistics!F8 | G14: =Statistics!G8 | H14: =Statistics!I8
A15: Rotation VAGG | B15: =Statistics!B9 | C15: =Statistics!C9 | D15: =Statistics!D9 | E15: =Statistics!E9 | F15: =Statistics!F9 | G15: =Statistics!G9 | H15: =Statistics!I9
A17: 2 · Forward-looking — after tax, same haircut, same contributions, to end age | H17: Benchmark haircut: | I17: =Dashboard!$C$10
A18: Portfolio | B18: Raw hist. CAGR | C18: Net expected | D18: Monthly | E18: Pre-tax balance | F18: After-tax balance | G18: vs glide path
A19: S&P 500 (SPY) | B19: 0.1098 | C19: =B19*(1-$I$17) | D19: =(1+C19)^(1/12)-1 | E19: =IF(ABS($D$19-Settings!$B$60)<0.000001,Dashboard!$C$7*(1+$D$19)^(Settings!$B$9*12)+Dashboard!$C$8*(Settings!$B$9*12)*(1+$D$19)^((Settings!$B$9*12)-1),Dashboard!$C$7*(1+$D$19)^(Settings!$B$9*12)+Dashboard!$C$8*(((1+$D$19)^(Settings!$B$9*12))-((1+Settings!$B$60)^(Settings!$B$9*12)))/($D$19-Settings!$B$60)) | F19: =$I$30+MAX(0,E19-$I$30)*(1-Dashboard!$C$12) | G19: =F19/$F$29-1
A20: Nasdaq 100 (QQQ) | B20: 0.1645 | C20: =B20*(1-$I$17) | D20: =(1+C20)^(1/12)-1 | E20: =IF(ABS($D$20-Settings!$B$60)<0.000001,Dashboard!$C$7*(1+$D$20)^(Settings!$B$9*12)+Dashboard!$C$8*(Settings!$B$9*12)*(1+$D$20)^((Settings!$B$9*12)-1),Dashboard!$C$7*(1+$D$20)^(Settings!$B$9*12)+Dashboard!$C$8*(((1+$D$20)^(Settings!$B$9*12))-((1+Settings!$B$60)^(Settings!$B$9*12)))/($D$20-Settings!$B$60)) | F20: =$I$30+MAX(0,E20-$I$30)*(1-Dashboard!$C$12) | G20: =F20/$F$29-1
A21: Dow Jones (DIA) | B21: 0.0978 | C21: =B21*(1-$I$17) | D21: =(1+C21)^(1/12)-1 | E21: =IF(ABS($D$21-Settings!$B$60)<0.000001,Dashboard!$C$7*(1+$D$21)^(Settings!$B$9*12)+Dashboard!$C$8*(Settings!$B$9*12)*(1+$D$21)^((Settings!$B$9*12)-1),Dashboard!$C$7*(1+$D$21)^(Settings!$B$9*12)+Dashboard!$C$8*(((1+$D$21)^(Settings!$B$9*12))-((1+Settings!$B$60)^(Settings!$B$9*12)))/($D$21-Settings!$B$60)) | F21: =$I$30+MAX(0,E21-$I$30)*(1-Dashboard!$C$12) | G21: =F21/$F$29-1
A22: 60/40 (SPY/AGG) | B22: 0.0817 | C22: =B22*(1-$I$17) | D22: =(1+C22)^(1/12)-1 | E22: =IF(ABS($D$22-Settings!$B$60)<0.000001,Dashboard!$C$7*(1+$D$22)^(Settings!$B$9*12)+Dashboard!$C$8*(Settings!$B$9*12)*(1+$D$22)^((Settings!$B$9*12)-1),Dashboard!$C$7*(1+$D$22)^(Settings!$B$9*12)+Dashboard!$C$8*(((1+$D$22)^(Settings!$B$9*12))-((1+Settings!$B$60)^(Settings!$B$9*12)))/($D$22-Settings!$B$60)) | F22: =$I$30+MAX(0,E22-$I$30)*(1-Dashboard!$C$12) | G22: =F22/$F$29-1
A23: All bonds (AGG) | B23: 0.0298 | C23: =B23*(1-$I$17) | D23: =(1+C23)^(1/12)-1 | E23: =IF(ABS($D$23-Settings!$B$60)<0.000001,Dashboard!$C$7*(1+$D$23)^(Settings!$B$9*12)+Dashboard!$C$8*(Settings!$B$9*12)*(1+$D$23)^((Settings!$B$9*12)-1),Dashboard!$C$7*(1+$D$23)^(Settings!$B$9*12)+Dashboard!$C$8*(((1+$D$23)^(Settings!$B$9*12))-((1+Settings!$B$60)^(Settings!$B$9*12)))/($D$23-Settings!$B$60)) | F23: =$I$30+MAX(0,E23-$I$30)*(1-Dashboard!$C$12) | G23: =F23/$F$29-1
A24: Gold (GLD) | B24: 0.0998 | C24: =B24*(1-$I$17) | D24: =(1+C24)^(1/12)-1 | E24: =IF(ABS($D$24-Settings!$B$60)<0.000001,Dashboard!$C$7*(1+$D$24)^(Settings!$B$9*12)+Dashboard!$C$8*(Settings!$B$9*12)*(1+$D$24)^((Settings!$B$9*12)-1),Dashboard!$C$7*(1+$D$24)^(Settings!$B$9*12)+Dashboard!$C$8*(((1+$D$24)^(Settings!$B$9*12))-((1+Settings!$B$60)^(Settings!$B$9*12)))/($D$24-Settings!$B$60)) | F24: =$I$30+MAX(0,E24-$I$30)*(1-Dashboard!$C$12) | G24: =F24/$F$29-1
A25: Rotation CONS | B25: =Statistics!$B$6 | C25: =Settings!$D$13 | D25: =(1+C25)^(1/12)-1 | E25: =IF(ABS($D$25-Settings!$B$60)<0.000001,Dashboard!$C$7*(1+$D$25)^(Settings!$B$9*12)+Dashboard!$C$8*(Settings!$B$9*12)*(1+$D$25)^((Settings!$B$9*12)-1),Dashboard!$C$7*(1+$D$25)^(Settings!$B$9*12)+Dashboard!$C$8*(((1+$D$25)^(Settings!$B$9*12))-((1+Settings!$B$60)^(Settings!$B$9*12)))/($D$25-Settings!$B$60)) | F25: =E25 | G25: =F25/$F$29-1
A26: Rotation MOD | B26: =Statistics!$B$7 | C26: =Settings!$D$14 | D26: =(1+C26)^(1/12)-1 | E26: =IF(ABS($D$26-Settings!$B$60)<0.000001,Dashboard!$C$7*(1+$D$26)^(Settings!$B$9*12)+Dashboard!$C$8*(Settings!$B$9*12)*(1+$D$26)^((Settings!$B$9*12)-1),Dashboard!$C$7*(1+$D$26)^(Settings!$B$9*12)+Dashboard!$C$8*(((1+$D$26)^(Settings!$B$9*12))-((1+Settings!$B$60)^(Settings!$B$9*12)))/($D$26-Settings!$B$60)) | F26: =E26 | G26: =F26/$F$29-1
A27: Rotation AGG | B27: =Statistics!$B$8 | C27: =Settings!$D$15 | D27: =(1+C27)^(1/12)-1 | E27: =IF(ABS($D$27-Settings!$B$60)<0.000001,Dashboard!$C$7*(1+$D$27)^(Settings!$B$9*12)+Dashboard!$C$8*(Settings!$B$9*12)*(1+$D$27)^((Settings!$B$9*12)-1),Dashboard!$C$7*(1+$D$27)^(Settings!$B$9*12)+Dashboard!$C$8*(((1+$D$27)^(Settings!$B$9*12))-((1+Settings!$B$60)^(Settings!$B$9*12)))/($D$27-Settings!$B$60)) | F27: =E27 | G27: =F27/$F$29-1
A28: Rotation VAGG | B28: =Statistics!$B$9 | C28: =Settings!$D$16 | D28: =(1+C28)^(1/12)-1 | E28: =IF(ABS($D$28-Settings!$B$60)<0.000001,Dashboard!$C$7*(1+$D$28)^(Settings!$B$9*12)+Dashboard!$C$8*(Settings!$B$9*12)*(1+$D$28)^((Settings!$B$9*12)-1),Dashboard!$C$7*(1+$D$28)^(Settings!$B$9*12)+Dashboard!$C$8*(((1+$D$28)^(Settings!$B$9*12))-((1+Settings!$B$60)^(Settings!$B$9*12)))/($D$28-Settings!$B$60)) | F28: =E28 | G28: =F28/$F$29-1
A29: YOUR GLIDE PATH (exact) | B29: =Statistics!$B$32 | F29: =INDEX(Projection!$E:$E,(Settings!$B$9*12)+4)
H30: Total contributed: | I30: =Dashboard!$C$7+12*SUM(Settings!$B$19:INDEX(Settings!$B$19:$B$58,MIN(40,Settings!$B$9)))
A31: Taxable-account model: rotation tiers taxed ANNUALLY at the ST rate (median regime 2 months — gains are short-term); buy-and-hold benchmarks compound pre-tax and pay the LT rate on gains at liquidation (deferral included; small dividend-tax drag omitted, slightly favoring benchmarks). One haircut on every row.

Sheet Projection
A1: Age-Aware Wealth Projection
A2: Each month uses the risk tier from the Dashboard glide path for that age. Low/High = ±1 s.e. on the average growth rate.
A4: Month | B4: Age | C4: Tier | D4: Contribution | E4: Expected | F4: Low | G4: High
A5: 1 | B5: =Dashboard!$C$5+(1-1)/12 | C5: =INDEX(Dashboard!$C$14:$C$21,MIN(8,INT((1-1)/60)+1)) | D5: =MIN(Dashboard!$C$9,INDEX(Settings!$B$19:$B$58,MIN(40,INT((1-1)/12)+1))) | E5: =Dashboard!$C$7*(1+INDEX(Settings!$E$13:$E$16,MATCH(C5,Settings!$A$13:$A$16,0)))+D5 | F5: =Dashboard!$C$7*(1+INDEX(Settings!$I$13:$I$16,MATCH(C5,Settings!$A$13:$A$16,0)))+D5 | G5: =Dashboard!$C$7*(1+INDEX(Settings!$J$13:$J$16,MATCH(C5,Settings!$A$13:$A$16,0)))+D5
A6: 2 | B6: =Dashboard!$C$5+(2-1)/12 | C6: =INDEX(Dashboard!$C$14:$C$21,MIN(8,INT((2-1)/60)+1)) | D6: =MIN(Dashboard!$C$9,INDEX(Settings!$B$19:$B$58,MIN(40,INT((2-1)/12)+1))) | E6: =E5*(1+INDEX(Settings!$E$13:$E$16,MATCH(C6,Settings!$A$13:$A$16,0)))+D6 | F6: =F5*(1+INDEX(Settings!$I$13:$I$16,MATCH(C6,Settings!$A$13:$A$16,0)))+D6 | G6: =G5*(1+INDEX(Settings!$J$13:$J$16,MATCH(C6,Settings!$A$13:$A$16,0)))+D6
A7: 3 | B7: =Dashboard!$C$5+(3-1)/12 | C7: =INDEX(Dashboard!$C$14:$C$21,MIN(8,INT((3-1)/60)+1)) | D7: =MIN(Dashboard!$C$9,INDEX(Settings!$B$19:$B$58,MIN(40,INT((3-1)/12)+1))) | E7: =E6*(1+INDEX(Settings!$E$13:$E$16,MATCH(C7,Settings!$A$13:$A$16,0)))+D7 | F7: =F6*(1+INDEX(Settings!$I$13:$I$16,MATCH(C7,Settings!$A$13:$A$16,0)))+D7 | G7: =G6*(1+INDEX(Settings!$J$13:$J$16,MATCH(C7,Settings!$A$13:$A$16,0)))+D7
A8: 4 | B8: =Dashboard!$C$5+(4-1)/12 | C8: =INDEX(Dashboard!$C$14:$C$21,MIN(8,INT((4-1)/60)+1)) | D8: =MIN(Dashboard!$C$9,INDEX(Settings!$B$19:$B$58,MIN(40,INT((4-1)/12)+1))) | E8: =E7*(1+INDEX(Settings!$E$13:$E$16,MATCH(C8,Settings!$A$13:$A$16,0)))+D8 | F8: =F7*(1+INDEX(Settings!$I$13:$I$16,MATCH(C8,Settings!$A$13:$A$16,0)))+D8 | G8: =G7*(1+INDEX(Settings!$J$13:$J$16,MATCH(C8,Settings!$A$13:$A$16,0)))+D8
A9: 5 | B9: =Dashboard!$C$5+(5-1)/12 | C9: =INDEX(Dashboard!$C$14:$C$21,MIN(8,INT((5-1)/60)+1)) | D9: =MIN(Dashboard!$C$9,INDEX(Settings!$B$19:$B$58,MIN(40,INT((5-1)/12)+1))) | E9: =E8*(1+INDEX(Settings!$E$13:$E$16,MATCH(C9,Settings!$A$13:$A$16,0)))+D9 | F9: =F8*(1+INDEX(Settings!$I$13:$I$16,MATCH(C9,Settings!$A$13:$A$16,0)))+D9 | G9: =G8*(1+INDEX(Settings!$J$13:$J$16,MATCH(C9,Settings!$A$13:$A$16,0)))+D9
A10: 6 | B10: =Dashboard!$C$5+(6-1)/12 | C10: =INDEX(Dashboard!$C$14:$C$21,MIN(8,INT((6-1)/60)+1)) | D10: =MIN(Dashboard!$C$9,INDEX(Settings!$B$19:$B$58,MIN(40,INT((6-1)/12)+1))) | E10: =E9*(1+INDEX(Settings!$E$13:$E$16,MATCH(C10,Settings!$A$13:$A$16,0)))+D10 | F10: =F9*(1+INDEX(Settings!$I$13:$I$16,MATCH(C10,Settings!$A$13:$A$16,0)))+D10 | G10: =G9*(1+INDEX(Settings!$J$13:$J$16,MATCH(C10,Settings!$A$13:$A$16,0)))+D10
A11: 7 | B11: =Dashboard!$C$5+(7-1)/12 | C11: =INDEX(Dashboard!$C$14:$C$21,MIN(8,INT((7-1)/60)+1)) | D11: =MIN(Dashboard!$C$9,INDEX(Settings!$B$19:$B$58,MIN(40,INT((7-1)/12)+1))) | E11: =E10*(1+INDEX(Settings!$E$13:$E$16,MATCH(C11,Settings!$A$13:$A$16,0)))+D11 | F11: =F10*(1+INDEX(Settings!$I$13:$I$16,MATCH(C11,Settings!$A$13:$A$16,0)))+D11 | G11: =G10*(1+INDEX(Settings!$J$13:$J$16,MATCH(C11,Settings!$A$13:$A$16,0)))+D11
A12: 8 | B12: =Dashboard!$C$5+(8-1)/12 | C12: =INDEX(Dashboard!$C$14:$C$21,MIN(8,INT((8-1)/60)+1)) | D12: =MIN(Dashboard!$C$9,INDEX(Settings!$B$19:$B$58,MIN(40,INT((8-1)/12)+1))) | E12: =E11*(1+INDEX(Settings!$E$13:$E$16,MATCH(C12,Settings!$A$13:$A$16,0)))+D12 | F12: =F11*(1+INDEX(Settings!$I$13:$I$16,MATCH(C12,Settings!$A$13:$A$16,0)))+D12 | G12: =G11*(1+INDEX(Settings!$J$13:$J$16,MATCH(C12,Settings!$A$13:$A$16,0)))+D12
A13: 9 | B13: =Dashboard!$C$5+(9-1)/12 | C13: =INDEX(Dashboard!$C$14:$C$21,MIN(8,INT((9-1)/60)+1)) | D13: =MIN(Dashboard!$C$9,INDEX(Settings!$B$19:$B$58,MIN(40,INT((9-1)/12)+1))) | E13: =E12*(1+INDEX(Settings!$E$13:$E$16,MATCH(C13,Settings!$A$13:$A$16,0)))+D13 | F13: =F12*(1+INDEX(Settings!$I$13:$I$16,MATCH(C13,Settings!$A$13:$A$16,0)))+D13 | G13: =G12*(1+INDEX(Settings!$J$13:$J$16,MATCH(C13,Settings!$A$13:$A$16,0)))+D13
A14: 10 | B14: =Dashboard!$C$5+(10-1)/12 | C14: =INDEX(Dashboard!$C$14:$C$21,MIN(8,INT((10-1)/60)+1)) | D14: =MIN(Dashboard!$C$9,INDEX(Settings!$B$19:$B$58,MIN(40,INT((10-1)/12)+1))) | E14: =E13*(1+INDEX(Settings!$E$13:$E$16,MATCH(C14,Settings!$A$13:$A$16,0)))+D14 | F14: =F13*(1+INDEX(Settings!$I$13:$I$16,MATCH(C14,Settings!$A$13:$A$16,0)))+D14 | G14: =G13*(1+INDEX(Settings!$J$13:$J$16,MATCH(C14,Settings!$A$13:$A$16,0)))+D14
A15: 11 | B15: =Dashboard!$C$5+(11-1)/12 | C15: =INDEX(Dashboard!$C$14:$C$21,MIN(8,INT((11-1)/60)+1)) | D15: =MIN(Dashboard!$C$9,INDEX(Settings!$B$19:$B$58,MIN(40,INT((11-1)/12)+1))) | E15: =E14*(1+INDEX(Settings!$E$13:$E$16,MATCH(C15,Settings!$A$13:$A$16,0)))+D15 | F15: =F14*(1+INDEX(Settings!$I$13:$I$16,MATCH(C15,Settings!$A$13:$A$16,0)))+D15 | G15: =G14*(1+INDEX(Settings!$J$13:$J$16,MATCH(C15,Settings!$A$13:$A$16,0)))+D15
A16: 12 | B16: =Dashboard!$C$5+(12-1)/12 | C16: =INDEX(Dashboard!$C$14:$C$21,MIN(8,INT((12-1)/60)+1)) | D16: =MIN(Dashboard!$C$9,INDEX(Settings!$B$19:$B$58,MIN(40,INT((12-1)/12)+1))) | E16: =E15*(1+INDEX(Settings!$E$13:$E$16,MATCH(C16,Settings!$A$13:$A$16,0)))+D16 | F16: =F15*(1+INDEX(Settings!$I$13:$I$16,MATCH(C16,Settings!$A$13:$A$16,0)))+D16 | G16: =G15*(1+INDEX(Settings!$J$13:$J$16,MATCH(C16,Settings!$A$13:$A$16,0)))+D16
A17: 13 | B17: =Dashboard!$C$5+(13-1)/12 | C17: =INDEX(Dashboard!$C$14:$C$21,MIN(8,INT((13-1)/60)+1)) | D17: =MIN(Dashboard!$C$9,INDEX(Settings!$B$19:$B$58,MIN(40,INT((13-1)/12)+1))) | E17: =E16*(1+INDEX(Settings!$E$13:$E$16,MATCH(C17,Settings!$A$13:$A$16,0)))+D17 | F17: =F16*(1+INDEX(Settings!$I$13:$I$16,MATCH(C17,Settings!$A$13:$A$16,0)))+D17 | G17: =G16*(1+INDEX(Settings!$J$13:$J$16,MATCH(C17,Settings!$A$13:$A$16,0)))+D17
A18: 14 | B18: =Dashboard!$C$5+(14-1)/12 | C18: =INDEX(Dashboard!$C$14:$C$21,MIN(8,INT((14-1)/60)+1)) | D18: =MIN(Dashboard!$C$9,INDEX(Settings!$B$19:$B$58,MIN(40,INT((14-1)/12)+1))) | E18: =E17*(1+INDEX(Settings!$E$13:$E$16,MATCH(C18,Settings!$A$13:$A$16,0)))+D18 | F18: =F17*(1+INDEX(Settings!$I$13:$I$16,MATCH(C18,Settings!$A$13:$A$16,0)))+D18 | G18: =G17*(1+INDEX(Settings!$J$13:$J$16,MATCH(C18,Settings!$A$13:$A$16,0)))+D18
A19: 15 | B19: =Dashboard!$C$5+(15-1)/12 | C19: =INDEX(Dashboard!$C$14:$C$21,MIN(8,INT((15-1)/60)+1)) | D19: =MIN(Dashboard!$C$9,INDEX(Settings!$B$19:$B$58,MIN(40,INT((15-1)/12)+1))) | E19: =E18*(1+INDEX(Settings!$E$13:$E$16,MATCH(C19,Settings!$A$13:$A$16,0)))+D19 | F19: =F18*(1+INDEX(Settings!$I$13:$I$16,MATCH(C19,Settings!$A$13:$A$16,0)))+D19 | G19: =G18*(1+INDEX(Settings!$J$13:$J$16,MATCH(C19,Settings!$A$13:$A$16,0)))+D19
A20: 16 | B20: =Dashboard!$C$5+(16-1)/12 | C20: =INDEX(Dashboard!$C$14:$C$21,MIN(8,INT((16-1)/60)+1)) | D20: =MIN(Dashboard!$C$9,INDEX(Settings!$B$19:$B$58,MIN(40,INT((16-1)/12)+1))) | E20: =E19*(1+INDEX(Settings!$E$13:$E$16,MATCH(C20,Settings!$A$13:$A$16,0)))+D20 | F20: =F19*(1+INDEX(Settings!$I$13:$I$16,MATCH(C20,Settings!$A$13:$A$16,0)))+D20 | G20: =G19*(1+INDEX(Settings!$J$13:$J$16,MATCH(C20,Settings!$A$13:$A$16,0)))+D20
A21: 17 | B21: =Dashboard!$C$5+(17-1)/12 | C21: =INDEX(Dashboard!$C$14:$C$21,MIN(8,INT((17-1)/60)+1)) | D21: =MIN(Dashboard!$C$9,INDEX(Settings!$B$19:$B$58,MIN(40,INT((17-1)/12)+1))) | E21: =E20*(1+INDEX(Settings!$E$13:$E$16,MATCH(C21,Settings!$A$13:$A$16,0)))+D21 | F21: =F20*(1+INDEX(Settings!$I$13:$I$16,MATCH(C21,Settings!$A$13:$A$16,0)))+D21 | G21: =G20*(1+INDEX(Settings!$J$13:$J$16,MATCH(C21,Settings!$A$13:$A$16,0)))+D21
A22: 18 | B22: =Dashboard!$C$5+(18-1)/12 | C22: =INDEX(Dashboard!$C$14:$C$21,MIN(8,INT((18-1)/60)+1)) | D22: =MIN(Dashboard!$C$9,INDEX(Settings!$B$19:$B$58,MIN(40,INT((18-1)/12)+1))) | E22: =E21*(1+INDEX(Settings!$E$13:$E$16,MATCH(C22,Settings!$A$13:$A$16,0)))+D22 | F22: =F21*(1+INDEX(Settings!$I$13:$I$16,MATCH(C22,Settings!$A$13:$A$16,0)))+D22 | G22: =G21*(1+INDEX(Settings!$J$13:$J$16,MATCH(C22,Settings!$A$13:$A$16,0)))+D22
A23: 19 | B23: =Dashboard!$C$5+(19-1)/12 | C23: =INDEX(Dashboard!$C$14:$C$21,MIN(8,INT((19-1)/60)+1)) | D23: =MIN(Dashboard!$C$9,INDEX(Settings!$B$19:$B$58,MIN(40,INT((19-1)/12)+1))) | E23: =E22*(1+INDEX(Settings!$E$13:$E$16,MATCH(C23,Settings!$A$13:$A$16,0)))+D23 | F23: =F22*(1+INDEX(Settings!$I$13:$I$16,MATCH(C23,Settings!$A$13:$A$16,0)))+D23 | G23: =G22*(1+INDEX(Settings!$J$13:$J$16,MATCH(C23,Settings!$A$13:$A$16,0)))+D23
A24: 20 | B24: =Dashboard!$C$5+(20-1)/12 | C24: =INDEX(Dashboard!$C$14:$C$21,MIN(8,INT((20-1)/60)+1)) | D24: =MIN(Dashboard!$C$9,INDEX(Settings!$B$19:$B$58,MIN(40,INT((20-1)/12)+1))) | E24: =E23*(1+INDEX(Settings!$E$13:$E$16,MATCH(C24,Settings!$A$13:$A$16,0)))+D24 | F24: =F23*(1+INDEX(Settings!$I$13:$I$16,MATCH(C24,Settings!$A$13:$A$16,0)))+D24 | G24: =G23*(1+INDEX(Settings!$J$13:$J$16,MATCH(C24,Settings!$A$13:$A$16,0)))+D24
A25: 21 | B25: =Dashboard!$C$5+(21-1)/12 | C25: =INDEX(Dashboard!$C$14:$C$21,MIN(8,INT((21-1)/60)+1)) | D25: =MIN(Dashboard!$C$9,INDEX(Settings!$B$19:$B$58,MIN(40,INT((21-1)/12)+1))) | E25: =E24*(1+INDEX(Settings!$E$13:$E$16,MATCH(C25,Settings!$A$13:$A$16,0)))+D25 | F25: =F24*(1+INDEX(Settings!$I$13:$I$16,MATCH(C25,Settings!$A$13:$A$16,0)))+D25 | G25: =G24*(1+INDEX(Settings!$J$13:$J$16,MATCH(C25,Settings!$A$13:$A$16,0)))+D25
A26: 22 | B26: =Dashboard!$C$5+(22-1)/12 | C26: =INDEX(Dashboard!$C$14:$C$21,MIN(8,INT((22-1)/60)+1)) | D26: =MIN(Dashboard!$C$9,INDEX(Settings!$B$19:$B$58,MIN(40,INT((22-1)/12)+1))) | E26: =E25*(1+INDEX(Settings!$E$13:$E$16,MATCH(C26,Settings!$A$13:$A$16,0)))+D26 | F26: =F25*(1+INDEX(Settings!$I$13:$I$16,MATCH(C26,Settings!$A$13:$A$16,0)))+D26 | G26: =G25*(1+INDEX(Settings!$J$13:$J$16,MATCH(C26,Settings!$A$13:$A$16,0)))+D26
A27: 23 | B27: =Dashboard!$C$5+(23-1)/12 | C27: =INDEX(Dashboard!$C$14:$C$21,MIN(8,INT((23-1)/60)+1)) | D27: =MIN(Dashboard!$C$9,INDEX(Settings!$B$19:$B$58,MIN(40,INT((23-1)/12)+1))) | E27: =E26*(1+INDEX(Settings!$E$13:$E$16,MATCH(C27,Settings!$A$13:$A$16,0)))+D27 | F27: =F26*(1+INDEX(Settings!$I$13:$I$16,MATCH(C27,Settings!$A$13:$A$16,0)))+D27 | G27: =G26*(1+INDEX(Settings!$J$13:$J$16,MATCH(C27,Settings!$A$13:$A$16,0)))+D27
A28: 24 | B28: =Dashboard!$C$5+(24-1)/12 | C28: =INDEX(Dashboard!$C$14:$C$21,MIN(8,INT((24-1)/60)+1)) | D28: =MIN(Dashboard!$C$9,INDEX(Settings!$B$19:$B$58,MIN(40,INT((24-1)/12)+1))) | E28: =E27*(1+INDEX(Settings!$E$13:$E$16,MATCH(C28,Settings!$A$13:$A$16,0)))+D28 | F28: =F27*(1+INDEX(Settings!$I$13:$I$16,MATCH(C28,Settings!$A$13:$A$16,0)))+D28 | G28: =G27*(1+INDEX(Settings!$J$13:$J$16,MATCH(C28,Settings!$A$13:$A$16,0)))+D28
A29: 25 | B29: =Dashboard!$C$5+(25-1)/12 | C29: =INDEX(Dashboard!$C$14:$C$21,MIN(8,INT((25-1)/60)+1)) | D29: =MIN(Dashboard!$C$9,INDEX(Settings!$B$19:$B$58,MIN(40,INT((25-1)/12)+1))) | E29: =E28*(1+INDEX(Settings!$E$13:$E$16,MATCH(C29,Settings!$A$13:$A$16,0)))+D29 | F29: =F28*(1+INDEX(Settings!$I$13:$I$16,MATCH(C29,Settings!$A$13:$A$16,0)))+D29 | G29: =G28*(1+INDEX(Settings!$J$13:$J$16,MATCH(C29,Settings!$A$13:$A$16,0)))+D29
A30: 26 | B30: =Dashboard!$C$5+(26-1)/12 | C30: =INDEX(Dashboard!$C$14:$C$21,MIN(8,INT((26-1)/60)+1)) | D30: =MIN(Dashboard!$C$9,INDEX(Settings!$B$19:$B$58,MIN(40,INT((26-1)/12)+1))) | E30: =E29*(1+INDEX(Settings!$E$13:$E$16,MATCH(C30,Settings!$A$13:$A$16,0)))+D30 | F30: =F29*(1+INDEX(Settings!$I$13:$I$16,MATCH(C30,Settings!$A$13:$A$16,0)))+D30 | G30: =G29*(1+INDEX(Settings!$J$13:$J$16,MATCH(C30,Settings!$A$13:$A$16,0)))+D30
A31: 27 | B31: =Dashboard!$C$5+(27-1)/12 | C31: =INDEX(Dashboard!$C$14:$C$21,MIN(8,INT((27-1)/60)+1)) | D31: =MIN(Dashboard!$C$9,INDEX(Settings!$B$19:$B$58,MIN(40,INT((27-1)/12)+1))) | E31: =E30*(1+INDEX(Settings!$E$13:$E$16,MATCH(C31,Settings!$A$13:$A$16,0)))+D31 | F31: =F30*(1+INDEX(Settings!$I$13:$I$16,MATCH(C31,Settings!$A$13:$A$16,0)))+D31 | G31: =G30*(1+INDEX(Settings!$J$13:$J$16,MATCH(C31,Settings!$A$13:$A$16,0)))+D31
A32: 28 | B32: =Dashboard!$C$5+(28-1)/12 | C32: =INDEX(Dashboard!$C$14:$C$21,MIN(8,INT((28-1)/60)+1)) | D32: =MIN(Dashboard!$C$9,INDEX(Settings!$B$19:$B$58,MIN(40,INT((28-1)/12)+1))) | E32: =E31*(1+INDEX(Settings!$E$13:$E$16,MATCH(C32,Settings!$A$13:$A$16,0)))+D32 | F32: =F31*(1+INDEX(Settings!$I$13:$I$16,MATCH(C32,Settings!$A$13:$A$16,0)))+D32 | G32: =G31*(1+INDEX(Settings!$J$13:$J$16,MATCH(C32,Settings!$A$13:$A$16,0)))+D32
A33: 29 | B33: =Dashboard!$C$5+(29-1)/12 | C33: =INDEX(Dashboard!$C$14:$C$21,MIN(8,INT((29-1)/60)+1)) | D33: =MIN(Dashboard!$C$9,INDEX(Settings!$B$19:$B$58,MIN(40,INT((29-1)/12)+1))) | E33: =E32*(1+INDEX(Settings!$E$13:$E$16,MATCH(C33,Settings!$A$13:$A$16,0)))+D33 | F33: =F32*(1+INDEX(Settings!$I$13:$I$16,MATCH(C33,Settings!$A$13:$A$16,0)))+D33 | G33: =G32*(1+INDEX(Settings!$J$13:$J$16,MATCH(C33,Settings!$A$13:$A$16,0)))+D33
A34: 30 | B34: =Dashboard!$C$5+(30-1)/12 | C34: =INDEX(Dashboard!$C$14:$C$21,MIN(8,INT((30-1)/60)+1)) | D34: =MIN(Dashboard!$C$9,INDEX(Settings!$B$19:$B$58,MIN(40,INT((30-1)/12)+1))) | E34: =E33*(1+INDEX(Settings!$E$13:$E$16,MATCH(C34,Settings!$A$13:$A$16,0)))+D34 | F34: =F33*(1+INDEX(Settings!$I$13:$I$16,MATCH(C34,Settings!$A$13:$A$16,0)))+D34 | G34: =G33*(1+INDEX(Settings!$J$13:$J$16,MATCH(C34,Settings!$A$13:$A$16,0)))+D34
A35: 31 | B35: =Dashboard!$C$5+(31-1)/12 | C35: =INDEX(Dashboard!$C$14:$C$21,MIN(8,INT((31-1)/60)+1)) | D35: =MIN(Dashboard!$C$9,INDEX(Settings!$B$19:$B$58,MIN(40,INT((31-1)/12)+1))) | E35: =E34*(1+INDEX(Settings!$E$13:$E$16,MATCH(C35,Settings!$A$13:$A$16,0)))+D35 | F35: =F34*(1+INDEX(Settings!$I$13:$I$16,MATCH(C35,Settings!$A$13:$A$16,0)))+D35 | G35: =G34*(1+INDEX(Settings!$J$13:$J$16,MATCH(C35,Settings!$A$13:$A$16,0)))+D35
A36: 32 | B36: =Dashboard!$C$5+(32-1)/12 | C36: =INDEX(Dashboard!$C$14:$C$21,MIN(8,INT((32-1)/60)+1)) | D36: =MIN(Dashboard!$C$9,INDEX(Settings!$B$19:$B$58,MIN(40,INT((32-1)/12)+1))) | E36: =E35*(1+INDEX(Settings!$E$13:$E$16,MATCH(C36,Settings!$A$13:$A$16,0)))+D36 | F36: =F35*(1+INDEX(Settings!$I$13:$I$16,MATCH(C36,Settings!$A$13:$A$16,0)))+D36 | G36: =G35*(1+INDEX(Settings!$J$13:$J$16,MATCH(C36,Settings!$A$13:$A$16,0)))+D36
A37: 33 | B37: =Dashboard!$C$5+(33-1)/12 | C37: =INDEX(Dashboard!$C$14:$C$21,MIN(8,INT((33-1)/60)+1)) | D37: =MIN(Dashboard!$C$9,INDEX(Settings!$B$19:$B$58,MIN(40,INT((33-1)/12)+1))) | E37: =E36*(1+INDEX(Settings!$E$13:$E$16,MATCH(C37,Settings!$A$13:$A$16,0)))+D37 | F37: =F36*(1+INDEX(Settings!$I$13:$I$16,MATCH(C37,Settings!$A$13:$A$16,0)))+D37 | G37: =G36*(1+INDEX(Settings!$J$13:$J$16,MATCH(C37,Settings!$A$13:$A$16,0)))+D37
A38: 34 | B38: =Dashboard!$C$5+(34-1)/12 | C38: =INDEX(Dashboard!$C$14:$C$21,MIN(8,INT((34-1)/60)+1)) | D38: =MIN(Dashboard!$C$9,INDEX(Settings!$B$19:$B$58,MIN(40,INT((34-1)/12)+1))) | E38: =E37*(1+INDEX(Settings!$E$13:$E$16,MATCH(C38,Settings!$A$13:$A$16,0)))+D38 | F38: =F37*(1+INDEX(Settings!$I$13:$I$16,MATCH(C38,Settings!$A$13:$A$16,0)))+D38 | G38: =G37*(1+INDEX(Settings!$J$13:$J$16,MATCH(C38,Settings!$A$13:$A$16,0)))+D38
A39: 35 | B39: =Dashboard!$C$5+(35-1)/12 | C39: =INDEX(Dashboard!$C$14:$C$21,MIN(8,INT((35-1)/60)+1)) | D39: =MIN(Dashboard!$C$9,INDEX(Settings!$B$19:$B$58,MIN(40,INT((35-1)/12)+1))) | E39: =E38*(1+INDEX(Settings!$E$13:$E$16,MATCH(C39,Settings!$A$13:$A$16,0)))+D39 | F39: =F38*(1+INDEX(Settings!$I$13:$I$16,MATCH(C39,Settings!$A$13:$A$16,0)))+D39 | G39: =G38*(1+INDEX(Settings!$J$13:$J$16,MATCH(C39,Settings!$A$13:$A$16,0)))+D39
A40: 36 | B40: =Dashboard!$C$5+(36-1)/12 | C40: =INDEX(Dashboard!$C$14:$C$21,MIN(8,INT((36-1)/60)+1)) | D40: =MIN(Dashboard!$C$9,INDEX(Settings!$B$19:$B$58,MIN(40,INT((36-1)/12)+1))) | E40: =E39*(1+INDEX(Settings!$E$13:$E$16,MATCH(C40,Settings!$A$13:$A$16,0)))+D40 | F40: =F39*(1+INDEX(Settings!$I$13:$I$16,MATCH(C40,Settings!$A$13:$A$16,0)))+D40 | G40: =G39*(1+INDEX(Settings!$J$13:$J$16,MATCH(C40,Settings!$A$13:$A$16,0)))+D40
A41: 37 | B41: =Dashboard!$C$5+(37-1)/12 | C41: =INDEX(Dashboard!$C$14:$C$21,MIN(8,INT((37-1)/60)+1)) | D41: =MIN(Dashboard!$C$9,INDEX(Settings!$B$19:$B$58,MIN(40,INT((37-1)/12)+1))) | E41: =E40*(1+INDEX(Settings!$E$13:$E$16,MATCH(C41,Settings!$A$13:$A$16,0)))+D41 | F41: =F40*(1+INDEX(Settings!$I$13:$I$16,MATCH(C41,Settings!$A$13:$A$16,0)))+D41 | G41: =G40*(1+INDEX(Settings!$J$13:$J$16,MATCH(C41,Settings!$A$13:$A$16,0)))+D41
...

Sheet Settings
A1: Advanced Settings
A2: Regime mix, frictions, contribution schedule, and the per-tier return engine. Yellow = edit.
A4: Expected regime mix (share of time)
B5: Growth | C5: Reflation | D5: Stagflation | E5: Deflation
A6: Weight | B6: 0.32 | C6: 0.47 | D6: 0.08 | E6: 0.13 | F6: =SUM(B6:E6) | G6: =IF(ABS(F6-1)>0.005,"← must sum to 100%","")
A8: Regime-switch cost drag (bps / yr) | B8: 60
A9: Horizon (years, from Dashboard ages) | B9: =Dashboard!$C$6-Dashboard!$C$5
A10: Backtest return haircut (%) | B10: =Dashboard!$C$10
A11: Per-tier return engine (derived — do not edit)
A12: Tier | B12: Mean monthly | C12: Annual (pre-tax) | D12: After-tax annual | E12: Net monthly | F12: Monthly sd | G12: Annual sd | H12: S.E. (avg) | I12: Low monthly | J12: High monthly
A13: CONS | B13: =(SUMPRODUCT($B$6:$E$6,Data!$B$6:$E$6)-$B$8/10000/12)*(1-$B$10) | C13: =(1+B13)^12-1 | D13: =IF(C13>0,C13*(1-Dashboard!$C$11),C13) | E13: =(1+D13)^(1/12)-1 | F13: =SUMPRODUCT($B$6:$E$6,Data!$B$13:$E$13) | G13: =F13*SQRT(12) | H13: =G13/SQRT(MAX(1,$B$9)) | I13: =(1+D13-H13)^(1/12)-1 | J13: =(1+D13+H13)^(1/12)-1
A14: MOD | B14: =(SUMPRODUCT($B$6:$E$6,Data!$B$7:$E$7)-$B$8/10000/12)*(1-$B$10) | C14: =(1+B14)^12-1 | D14: =IF(C14>0,C14*(1-Dashboard!$C$11),C14) | E14: =(1+D14)^(1/12)-1 | F14: =SUMPRODUCT($B$6:$E$6,Data!$B$14:$E$14) | G14: =F14*SQRT(12) | H14: =G14/SQRT(MAX(1,$B$9)) | I14: =(1+D14-H14)^(1/12)-1 | J14: =(1+D14+H14)^(1/12)-1
A15: AGG | B15: =(SUMPRODUCT($B$6:$E$6,Data!$B$8:$E$8)-$B$8/10000/12)*(1-$B$10) | C15: =(1+B15)^12-1 | D15: =IF(C15>0,C15*(1-Dashboard!$C$11),C15) | E15: =(1+D15)^(1/12)-1 | F15: =SUMPRODUCT($B$6:$E$6,Data!$B$15:$E$15) | G15: =F15*SQRT(12) | H15: =G15/SQRT(MAX(1,$B$9)) | I15: =(1+D15-H15)^(1/12)-1 | J15: =(1+D15+H15)^(1/12)-1
A16: VAGG | B16: =(SUMPRODUCT($B$6:$E$6,Data!$B$9:$E$9)-$B$8/10000/12)*(1-$B$10) | C16: =(1+B16)^12-1 | D16: =IF(C16>0,C16*(1-Dashboard!$C$11),C16) | E16: =(1+D16)^(1/12)-1 | F16: =SUMPRODUCT($B$6:$E$6,Data!$B$16:$E$16) | G16: =F16*SQRT(12) | H16: =G16/SQRT(MAX(1,$B$9)) | I16: =(1+D16-H16)^(1/12)-1 | J16: =(1+D16+H16)^(1/12)-1
A18: Contribution schedule — driven by the RAMP STAGES table (edit the yellow rates)
A19: Year 1 | B19: =Dashboard!$C$8 | D19: Ramp stage | E19: From yr | F19: Growth %/yr
A20: Year 2 | B20: =ROUND(B19*(1+INDEX($F$20:$F$32,MATCH(2,$E$20:$E$32,1)))/25,0)*25 | D20: Ages 26-28 | E20: 2 | F20: 0.35
A21: Year 3 | B21: =ROUND(B20*(1+INDEX($F$20:$F$32,MATCH(3,$E$20:$E$32,1)))/25,0)*25 | D21: Ages 29-31 | E21: 5 | F21: 0.15
A22: Year 4 | B22: =ROUND(B21*(1+INDEX($F$20:$F$32,MATCH(4,$E$20:$E$32,1)))/25,0)*25 | D22: Ages 32-34 | E22: 8 | F22: 0.1
A23: Year 5 | B23: =ROUND(B22*(1+INDEX($F$20:$F$32,MATCH(5,$E$20:$E$32,1)))/25,0)*25 | D23: Ages 35-37 | E23: 11 | F23: 0.08
A24: Year 6 | B24: =ROUND(B23*(1+INDEX($F$20:$F$32,MATCH(6,$E$20:$E$32,1)))/25,0)*25 | D24: Ages 38-40 | E24: 14 | F24: 0.08
A25: Year 7 | B25: =ROUND(B24*(1+INDEX($F$20:$F$32,MATCH(7,$E$20:$E$32,1)))/25,0)*25 | D25: Ages 41-43 | E25: 17 | F25: 0.07
A26: Year 8 | B26: =ROUND(B25*(1+INDEX($F$20:$F$32,MATCH(8,$E$20:$E$32,1)))/25,0)*25 | D26: Ages 44-46 | E26: 20 | F26: 0.07
A27: Year 9 | B27: =ROUND(B26*(1+INDEX($F$20:$F$32,MATCH(9,$E$20:$E$32,1)))/25,0)*25 | D27: Ages 47-49 | E27: 23 | F27: 0.07
A28: Year 10 | B28: =ROUND(B27*(1+INDEX($F$20:$F$32,MATCH(10,$E$20:$E$32,1)))/25,0)*25 | D28: Ages 50-52 | E28: 26 | F28: 0.06
A29: Year 11 | B29: =ROUND(B28*(1+INDEX($F$20:$F$32,MATCH(11,$E$20:$E$32,1)))/25,0)*25 | D29: Ages 53-55 | E29: 29 | F29: 0.06
A30: Year 12 | B30: =ROUND(B29*(1+INDEX($F$20:$F$32,MATCH(12,$E$20:$E$32,1)))/25,0)*25 | D30: Ages 56-58 | E30: 32 | F30: 0.05
A31: Year 13 | B31: =ROUND(B30*(1+INDEX($F$20:$F$32,MATCH(13,$E$20:$E$32,1)))/25,0)*25 | D31: Ages 59-61 | E31: 35 | F31: 0.05
A32: Year 14 | B32: =ROUND(B31*(1+INDEX($F$20:$F$32,MATCH(14,$E$20:$E$32,1)))/25,0)*25 | D32: Ages 62-64 | E32: 38 | F32: 0.05
A33: Year 15 | B33: =ROUND(B32*(1+INDEX($F$20:$F$32,MATCH(15,$E$20:$E$32,1)))/25,0)*25
A34: Year 16 | B34: =ROUND(B33*(1+INDEX($F$20:$F$32,MATCH(16,$E$20:$E$32,1)))/25,0)*25
A35: Year 17 | B35: =ROUND(B34*(1+INDEX($F$20:$F$32,MATCH(17,$E$20:$E$32,1)))/25,0)*25
A36: Year 18 | B36: =ROUND(B35*(1+INDEX($F$20:$F$32,MATCH(18,$E$20:$E$32,1)))/25,0)*25
A37: Year 19 | B37: =ROUND(B36*(1+INDEX($F$20:$F$32,MATCH(19,$E$20:$E$32,1)))/25,0)*25
A38: Year 20 | B38: =ROUND(B37*(1+INDEX($F$20:$F$32,MATCH(20,$E$20:$E$32,1)))/25,0)*25
A39: Year 21 | B39: =ROUND(B38*(1+INDEX($F$20:$F$32,MATCH(21,$E$20:$E$32,1)))/25,0)*25
A40: Year 22 | B40: =ROUND(B39*(1+INDEX($F$20:$F$32,MATCH(22,$E$20:$E$32,1)))/25,0)*25
A41: Year 23 | B41: =ROUND(B40*(1+INDEX($F$20:$F$32,MATCH(23,$E$20:$E$32,1)))/25,0)*25
A42: Year 24 | B42: =ROUND(B41*(1+INDEX($F$20:$F$32,MATCH(24,$E$20:$E$32,1)))/25,0)*25
A43: Year 25 | B43: =ROUND(B42*(1+INDEX($F$20:$F$32,MATCH(25,$E$20:$E$32,1)))/25,0)*25
...

Sheet Data
A1: Model Data — per-regime return statistics (matrix v9, monthly-only execution, Jan 2007–Sep 2026)
A2: Blue = editable assumption. Rotation sleeve only; options overlay excluded.
A4: Mean monthly return
B5: Growth | C5: Reflation | D5: Stagflation | E5: Deflation
A6: CONS | B6: 0.00729 | C6: 0.00828 | D6: 0.00398 | E6: 0.01164
A7: MOD | B7: 0.01371 | C7: 0.01118 | D7: 0.00648 | E7: 0.01795
A8: AGG | B8: 0.03308 | C8: 0.01427 | D8: 0.00804 | E8: 0.03473
A9: VAGG | B9: 0.04851 | C9: 0.01752 | D9: 0.00869 | E9: 0.04287
A11: Monthly standard deviation
B12: Growth | C12: Reflation | D12: Stagflation | E12: Deflation
A13: CONS | B13: 0.01753 | C13: 0.02252 | D13: 0.01519 | E13: 0.0323
A14: MOD | B14: 0.03052 | C14: 0.03221 | D14: 0.02411 | E14: 0.035
A15: AGG | B15: 0.09041 | C15: 0.04384 | D15: 0.03079 | E15: 0.07679
A16: VAGG | B16: 0.13714 | C16: 0.06011 | D16: 0.03353 | E16: 0.09958
A18: Regime structure & risk-free
B19: Growth | C19: Reflation | D19: Stagflation | E19: Deflation
A20: Share of months | B20: 0.321 | C20: 0.473 | D20: 0.08 | E20: 0.127
A21: Avg duration (months) | B21: 3.2 | C21: 5.3 | D21: 2.7 | E21: 2.3
A23: Risk-free rate (annual) | B23: 0.019

Sheet Methodology
A1: Methodology & Assumptions
A3: Glide path
A4: The Dashboard assigns a risk tier to each 5-year age block (age 25→65 = 8 decision points). The projection applies each block's tier return, switching automatically at block boundaries. Defaults de-risk with age: VAGG→AGG→MOD→CONS.
A6: Framework
A7: Four macro regimes (growth x inflation) classified monthly ex-ante (SPY & DBC vs 10-month SMAs, locked). Each tier = fixed allocation per regime (matrix v2). Per-tier expected returns blend per-regime statistics by the Settings regime mix, minus switch-cost drag.
A9: Contributions
A10: Year-by-year monthly schedule on Settings (defaults: $1,500/mo yr1 per user 2026 update; +20%/yr through yr5, +7%/yr after — anchored to user decade targets: >$5k/mo in 30s, >$7k in 40s, >$10k in 50s), capped on the Dashboard. Projection applies the exact schedule.
A12: Uncertainty
A13: Low/High paths and Statistics percentiles band the uncertainty of the AVERAGE growth rate (+/- s.e. = annual sd / sqrt(horizon years)). They are not drawdown bounds: backtested max drawdowns are CONS -13%, MOD -15%, AGG -37%, VAGG -51%, and a VAGG-heavy early glide will experience them.
A15: Return haircut
A16: Long-horizon compounding of raw backtest returns is not credible (edges decay; regimes shift; capacity and execution erode results). The Dashboard haircut (default 25%) scales all tier returns down before projecting. Set 0% to see raw-backtest numbers; treat those as an upper bound, not a plan.
A18: Evidence quality
... A28: Personal research tooling; not investment advice. Past and simulated performance do not guarantee future results.
